<?xml version="1.0"?>
<robot name="omni_robot" xmlns:xacro="http://www.ros.org/wiki/xacro">

    <!-- Define a number of dimensions using properties -->
    <xacro:property name="base_size_x" value="0.30" />
    <xacro:property name="base_size_y" value="0.30" />
    <xacro:property name="base_size_z" value="0.12" />
    <xacro:property name="wheel_length" value="0.02" />
    <xacro:property name="wheel_radius" value="0.06" />
    <xacro:property name="roller_length" value="0.025" />
    <xacro:property name="roller_radius" value="0.01" />
    <xacro:property name="wheel_offset_x" value="0.09" />
    <xacro:property name="wheel_offset_y" value="0.17" />
    <xacro:property name="wheel_offset_z" value="-0.038" />

    <property name="PI" value="3.1415" />
    <xacro:include filename="$(find fira6_description)/urdf/materials.urdf.xacro" />


    <link name="base_footprint"/>
        <!--visual>
            <origin xyz="0 0 0" rpy="0 0 0" />
            <geometry>
                <box size="0.1 0.1 0.01" />
            </geometry>
        </visual>
        <collision>
            <origin xyz="0 0 0" rpy="0 0 0" />
            <geometry>
                <box size="0.1 0.1 0.01" />
            </geometry>
        </collision>
    </link-->

    <joint name="base_joint" type="fixed">
        <origin xyz="0 0 ${base_size_z/2}" rpy="0 0 0" />
        <child link="base_footprint"/>
        <parent link="base_link" />
    </joint>

    <link name="base_link">
        <visual>
            <origin xyz="0 0 0" rpy="0 0 1.57" />
            <geometry>
                <box size="${base_size_x} ${base_size_y} ${base_size_z}" />
		<!--mesh filename="package://fira6_description/meshes/fira6.STL" scale="0.001 0.001 0.001"/-->
            </geometry>
        </visual>
        <collision>
            <origin xyz="0 0 0" rpy="0 0 0" />
            <geometry>
                <box size="${base_size_x} ${base_size_y} ${base_size_z}" />
            </geometry>
        </collision>
    	<inertial>
            <mass value="50" />
      	    <origin xyz="0 0 0" />
      	    <inertia ixx="0.435" ixy="0.0"  ixz="0.0"
        	     iyy="0.435" iyz="0.0"
        	     izz="0.75" />
    	</inertial>
    </link>

  <joint name="hokuyo_joint" type="fixed">
    <axis xyz="0 0 0" />
    <origin xyz="0 0 ${base_size_z/2+0.05}" rpy="0 0 0"/>
    <parent link="base_link"/>
    <child link="hokuyo_link"/>
  </joint>

  <!-- Hokuyo Laser -->
  <link name="hokuyo_link">
    <collision>
      <origin xyz="0 0 0" rpy="0 0 0"/>
      <geometry>
	<box size="0.1 0.1 0.1"/>
      </geometry>
    </collision>

    <visual>
      <origin xyz="0 0 0" rpy="0 0 0"/>
      <geometry>
        <mesh filename="package://rrbot_description/meshes/hokuyo.dae"/>
      </geometry>
    </visual>

    <inertial>
      <mass value="1e-5" />
      <origin xyz="0 0 0" rpy="0 0 0"/>
      <inertia ixx="1e-6" ixy="0" ixz="0" iyy="1e-6" iyz="0" izz="1e-6" />
    </inertial>
  </link>

  <!-- hokuyo -->
  <gazebo reference="hokuyo_link">
    <sensor type="gpu_ray" name="head_hokuyo_sensor">
      <pose>0 0 0 0 0 0</pose>
      <visualize>false</visualize>
      <update_rate>40</update_rate>
      <ray>
        <scan>
          <horizontal>
            <samples>720</samples>
            <resolution>1</resolution>
            <min_angle>-1.570796</min_angle>
            <max_angle>1.570796</max_angle>
          </horizontal>
        </scan>
        <range>
          <min>0.10</min>
          <max>30.0</max>
          <resolution>0.01</resolution>
        </range>
        <noise>
          <type>gaussian</type>
          <!-- Noise parameters based on published spec for Hokuyo laser
               achieving "+-30mm" accuracy at range < 10m.  A mean of 0.0m and
               stddev of 0.01m will put 99.7% of samples within 0.03m of the true
               reading. -->
          <mean>0.0</mean>
          <stddev>0.01</stddev>
        </noise>
      </ray>
      <plugin name="gazebo_ros_head_hokuyo_controller" filename="libgazebo_ros_gpu_laser.so">
        <topicName>/scan</topicName>
        <frameName>hokuyo_link</frameName>
      </plugin>
    </sensor>
  </gazebo>

    <macro name="omni_wheel" params="suffix parent reflect">
        <joint name="${parent}_${suffix}_wheel_joint" type="continuous">
            <axis xyz="0 0 1" />
            <limit effort="100" velocity="100"/>
            <safety_controller k_velocity="10" />
            <origin xyz="${wheel_offset_x} ${reflect*wheel_offset_y} ${wheel_offset_z}" rpy="${reflect*PI/2} 0 ${-0.5233*reflect}" />
            <parent link="${parent}_link"/>
            <child link="omni_${suffix}_wheel_link"/>
        </joint>
        <link name="omni_${suffix}_wheel_link">
            <visual>
                <origin xyz="0 0 0" rpy="0 0 0" />
                <geometry>
                    <cylinder radius="${wheel_radius}" length="${wheel_length}"/>
                </geometry>
                <material name="Orange" />
            </visual>
            <collision>
                <origin xyz="0 0 0" rpy="0 0 0" />
                <geometry>
                    <cylinder radius="${wheel_radius}" length="${wheel_length}"/>
                </geometry>
                <material name="Orange" />
            </collision>
    	    <inertial>
                <mass value="5" />
          	    <origin xyz="0 0 0" />
          	    <inertia ixx="0.0047" ixy="0.0"  ixz="0.0"
            		                iyy="0.0047" iyz="0.0"
	        				     izz="0.0015" />
    	    </inertial>
        </link>

        <joint name = "${suffix}_wheel_roller_joint1" type="continuous">
            <axis xyz="0 1 0" />
            <limit effort="100" velocity="100"/>
            <origin xyz="${wheel_radius} 0 0" rpy="0 0 0" />
            <parent link="omni_${suffix}_wheel_link"/>
            <child link="${suffix}_roller_link1"/>
        </joint>

        <link name="${suffix}_roller_link1">
            <visual>
                <origin xyz="0 0 0" rpy="1.57 0 0" />
                <geometry>
                    <cylinder radius="${roller_radius}" length="${roller_length}"/>
                </geometry>
                <material name="OffWhite" />
            </visual>
            <collision>
                <origin xyz="0 0 0" rpy="1.57 0 0" />
                <geometry>
                    <cylinder radius="${roller_radius}" length="${roller_length}"/>
                </geometry>
                <material name="OffWhite" />
            </collision>
    	    <inertial>
                <mass value="0.1" />
          	    <origin xyz="0 0 0" />
          	    <inertia ixx="0.00001" ixy="0.0"  ixz="0.0"
            				iyy="0.00001" iyz="0.0"
					              izz="0.000005" />
    	    </inertial>
        </link>

        <joint name = "${suffix}_wheel_roller_joint2" type="continuous">
            <axis xyz="0 1 0" />
            <limit effort="100" velocity="100"/>
            <origin xyz="${wheel_radius*0.866} ${wheel_radius*0.5} 0" rpy="0 0 0.5233" />
            <parent link="omni_${suffix}_wheel_link"/>
            <child link="${suffix}_roller_link2"/>
        </joint>

        <link name="${suffix}_roller_link2">
            <visual>
                <origin xyz="0 0 0" rpy="1.57 0 0" />
                <geometry>
                    <cylinder radius="${roller_radius}" length="${roller_length}"/>
                </geometry>
                <material name="OffWhite" />
            </visual>
            <collision>
                <origin xyz="0 0 0" rpy="1.57 0 0" />
                <geometry>
                    <cylinder radius="${roller_radius}" length="${roller_length}"/>
                </geometry>
                <material name="OffWhite" />
            </collision>
    	    <inertial>
                <mass value="0.1" />
          	    <origin xyz="0 0 0" />
          	    <inertia ixx="0.00001" ixy="0.0"  ixz="0.0"
            				iyy="0.00001" iyz="0.0"
					              izz="0.000005" />
    	    </inertial>
        </link>
        <joint name = "${suffix}_wheel_roller_joint3" type="continuous">
            <axis xyz="0 1 0" />
            <limit effort="100" velocity="100"/>
            <origin xyz="${wheel_radius*0.5} ${wheel_radius*0.866} 0" rpy="0 0 1.0467" />
            <parent link="omni_${suffix}_wheel_link"/>
            <child link="${suffix}_roller_link3"/>
        </joint>

        <link name="${suffix}_roller_link3">
            <visual>
                <origin xyz="0 0 0" rpy="1.57 0 0" />
                <geometry>
                    <cylinder radius="${roller_radius}" length="${roller_length}"/>
                </geometry>
                <material name="OffWhite" />
            </visual>
            <collision>
                <origin xyz="0 0 0" rpy="1.57 0 0" />
                <geometry>
                    <cylinder radius="${roller_radius}" length="${roller_length}"/>
                </geometry>
                <material name="OffWhite" />
            </collision>
    	    <inertial>
                <mass value="0.1" />
          	    <origin xyz="0 0 0" />
          	    <inertia ixx="0.00001" ixy="0.0"  ixz="0.0"
            				iyy="0.00001" iyz="0.0"
					              izz="0.000005" />
    	    </inertial>
        </link>
        <joint name = "${suffix}_wheel_roller_joint4" type="continuous">
            <axis xyz="0 1 0" />
            <limit effort="100" velocity="100"/>
            <origin xyz="0 ${wheel_radius*1} 0" rpy="0 0 1.57" />
            <parent link="omni_${suffix}_wheel_link"/>
            <child link="${suffix}_roller_link4"/>
        </joint>

        <link name="${suffix}_roller_link4">
            <visual>
                <origin xyz="0 0 0" rpy="1.57 0 0" />
                <geometry>
                    <cylinder radius="${roller_radius}" length="${roller_length}"/>
                </geometry>
                <material name="OffWhite" />
            </visual>
            <collision>
                <origin xyz="0 0 0" rpy="1.57 0 0" />
                <geometry>
                    <cylinder radius="${roller_radius}" length="${roller_length}"/>
                </geometry>
                <material name="OffWhite" />
            </collision>
    	    <inertial>
                <mass value="0.1" />
          	    <origin xyz="0 0 0" />
          	    <inertia ixx="0.00001" ixy="0.0"  ixz="0.0"
            				iyy="0.00001" iyz="0.0"
					              izz="0.000005" />
    	    </inertial>
        </link>
        <joint name = "${suffix}_wheel_roller_joint5" type="continuous">
            <axis xyz="0 1 0" />
            <limit effort="100" velocity="100"/>
            <origin xyz="${wheel_radius*-0.5} ${wheel_radius*0.866} 0" rpy="0 0 2.093" />
            <parent link="omni_${suffix}_wheel_link"/>
            <child link="${suffix}_roller_link5"/>
        </joint>

        <link name="${suffix}_roller_link5">
            <visual>
                <origin xyz="0 0 0" rpy="1.57 0 0" />
                <geometry>
                    <cylinder radius="${roller_radius}" length="${roller_length}"/>
                </geometry>
                <material name="OffWhite" />
            </visual>
            <collision>
                <origin xyz="0 0 0" rpy="1.57 0 0" />
                <geometry>
                    <cylinder radius="${roller_radius}" length="${roller_length}"/>
                </geometry>
                <material name="OffWhite" />
            </collision>
    	    <inertial>
                <mass value="0.1" />
          	    <origin xyz="0 0 0" />
          	    <inertia ixx="0.00001" ixy="0.0"  ixz="0.0"
            				iyy="0.00001" iyz="0.0"
					              izz="0.000005" />
    	    </inertial>
        </link>
        <joint name = "${suffix}_wheel_roller_joint6" type="continuous">
            <axis xyz="0 1 0" />
            <limit effort="100" velocity="100"/>
            <origin xyz="${wheel_radius*-0.866} ${wheel_radius*0.5} 0" rpy="0 0 2.617" />
            <parent link="omni_${suffix}_wheel_link"/>
            <child link="${suffix}_roller_link6"/>
        </joint>

        <link name="${suffix}_roller_link6">
            <visual>
                <origin xyz="0 0 0" rpy="1.57 0 0" />
                <geometry>
                    <cylinder radius="${roller_radius}" length="${roller_length}"/>
                </geometry>
                <material name="OffWhite" />
            </visual>
            <collision>
                <origin xyz="0 0 0" rpy="1.57 0 0" />
                <geometry>
                    <cylinder radius="${roller_radius}" length="${roller_length}"/>
                </geometry>
                <material name="OffWhite" />
            </collision>
    	    <inertial>
                <mass value="0.1" />
          	    <origin xyz="0 0 0" />
          	    <inertia ixx="0.00001" ixy="0.0"  ixz="0.0"
            				iyy="0.00001" iyz="0.0"
					              izz="0.000005" />
    	    </inertial>
        </link>
        <joint name = "${suffix}_wheel_roller_joint7" type="continuous">
            <axis xyz="0 1 0" />
            <limit effort="100" velocity="100"/>
            <origin xyz="${wheel_radius*-1} ${wheel_radius*0} 0" rpy="0 0 3.14" />
            <parent link="omni_${suffix}_wheel_link"/>
            <child link="${suffix}_roller_link7"/>
        </joint>

        <link name="${suffix}_roller_link7">
            <visual>
                <origin xyz="0 0 0" rpy="1.57 0 0" />
                <geometry>
                    <cylinder radius="${roller_radius}" length="${roller_length}"/>
                </geometry>
                <material name="OffWhite" />
            </visual>
            <collision>
                <origin xyz="0 0 0" rpy="1.57 0 0" />
                <geometry>
                    <cylinder radius="${roller_radius}" length="${roller_length}"/>
                </geometry>
                <material name="OffWhite" />
            </collision>
    	    <inertial>
                <mass value="0.1" />
          	    <origin xyz="0 0 0" />
          	    <inertia ixx="0.00001" ixy="0.0"  ixz="0.0"
            				iyy="0.00001" iyz="0.0"
					              izz="0.000005" />
    	    </inertial>
        </link>
        <joint name = "${suffix}_wheel_roller_joint8" type="continuous">
            <axis xyz="0 1 0" />
            <limit effort="100" velocity="100"/>
            <origin xyz="${wheel_radius*-0.866} ${wheel_radius*-0.5} 0" rpy="0 0 3.66" />
            <parent link="omni_${suffix}_wheel_link"/>
            <child link="${suffix}_roller_link8"/>
        </joint>

        <link name="${suffix}_roller_link8">
            <visual>
                <origin xyz="0 0 0" rpy="1.57 0 0" />
                <geometry>
                    <cylinder radius="${roller_radius}" length="${roller_length}"/>
                </geometry>
                <material name="OffWhite" />
            </visual>
            <collision>
                <origin xyz="0 0 0" rpy="1.57 0 0" />
                <geometry>
                    <cylinder radius="${roller_radius}" length="${roller_length}"/>
                </geometry>
                <material name="OffWhite" />
            </collision>
    	    <inertial>
                <mass value="0.1" />
          	    <origin xyz="0 0 0" />
          	    <inertia ixx="0.00001" ixy="0.0"  ixz="0.0"
            				iyy="0.00001" iyz="0.0"
					              izz="0.000005" />
    	    </inertial>
        </link>
	<joint name = "${suffix}_wheel_roller_joint9" type="continuous">
            <axis xyz="0 1 0" />
            <limit effort="100" velocity="100"/>
            <origin xyz="${wheel_radius*-0.5} ${wheel_radius*-0.866} 0" rpy="0 0 4.187" />
            <parent link="omni_${suffix}_wheel_link"/>
            <child link="${suffix}_roller_link9"/>
        </joint>

        <link name="${suffix}_roller_link9">
            <visual>
                <origin xyz="0 0 0" rpy="1.57 0 0" />
                <geometry>
                    <cylinder radius="${roller_radius}" length="${roller_length}"/>
                </geometry>
                <material name="OffWhite" />
            </visual>
            <collision>
                <origin xyz="0 0 0" rpy="1.57 0 0" />
                <geometry>
                    <cylinder radius="${roller_radius}" length="${roller_length}"/>
                </geometry>
                <material name="OffWhite" />
            </collision>
    	    <inertial>
                <mass value="0.1" />
          	    <origin xyz="0 0 0" />
          	    <inertia ixx="0.00001" ixy="0.0"  ixz="0.0"
            				iyy="0.00001" iyz="0.0"
					              izz="0.000005" />
    	    </inertial>
        </link>
	<joint name = "${suffix}_wheel_roller_joint10" type="continuous">
            <axis xyz="0 1 0" />
            <limit effort="100" velocity="100"/>
            <origin xyz="${wheel_radius*0} ${wheel_radius*-1} 0" rpy="0 0 4.71" />
            <parent link="omni_${suffix}_wheel_link"/>
            <child link="${suffix}_roller_link10"/>
        </joint>

        <link name="${suffix}_roller_link10">
            <visual>
                <origin xyz="0 0 0" rpy="1.57 0 0" />
                <geometry>
                    <cylinder radius="${roller_radius}" length="${roller_length}"/>
                </geometry>
                <material name="OffWhite" />
            </visual>
            <collision>
                <origin xyz="0 0 0" rpy="1.57 0 0" />
                <geometry>
                    <cylinder radius="${roller_radius}" length="${roller_length}"/>
                </geometry>
                <material name="OffWhite" />
            </collision>
    	    <inertial>
                <mass value="0.1" />
          	    <origin xyz="0 0 0" />
          	    <inertia ixx="0.00001" ixy="0.0"  ixz="0.0"
            				iyy="0.00001" iyz="0.0"
					              izz="0.000005" />
    	    </inertial>
        </link>
	<joint name = "${suffix}_wheel_roller_joint11" type="continuous">
            <axis xyz="0 1 0" />
            <limit effort="100" velocity="100"/>
            <origin xyz="${wheel_radius*0.5} ${wheel_radius*-0.866} 0" rpy="0 0 5.233" />
            <parent link="omni_${suffix}_wheel_link"/>
            <child link="${suffix}_roller_link11"/>
        </joint>

        <link name="${suffix}_roller_link11">
            <visual>
                <origin xyz="0 0 0" rpy="1.57 0 0" />
                <geometry>
                    <cylinder radius="${roller_radius}" length="${roller_length}"/>
                </geometry>
                <material name="OffWhite" />
            </visual>
            <collision>
                <origin xyz="0 0 0" rpy="1.57 0 0" />
                <geometry>
                    <cylinder radius="${roller_radius}" length="${roller_length}"/>
                </geometry>
                <material name="OffWhite" />
            </collision>
    	    <inertial>
                <mass value="0.1" />
          	    <origin xyz="0 0 0" />
          	    <inertia ixx="0.00001" ixy="0.0"  ixz="0.0"
            				iyy="0.00001" iyz="0.0"
					              izz="0.000005" />
    	    </inertial>
        </link>
	<joint name = "${suffix}_wheel_roller_joint12" type="continuous">
            <axis xyz="0 1 0" />
            <limit effort="100" velocity="100"/>
            <origin xyz="${wheel_radius*0.866} ${wheel_radius*-0.5} 0" rpy="0 0 5.757" />
            <parent link="omni_${suffix}_wheel_link"/>
            <child link="${suffix}_roller_link12"/>
        </joint>

        <link name="${suffix}_roller_link12">
            <visual>
                <origin xyz="0 0 0" rpy="1.57 0 0" />
                <geometry>
                    <cylinder radius="${roller_radius}" length="${roller_length}"/>
                </geometry>
                <material name="OffWhite" />
            </visual>
            <collision>
                <origin xyz="0 0 0" rpy="1.57 0 0" />
                <geometry>
                    <cylinder radius="${roller_radius}" length="${roller_length}"/>
                </geometry>
                <material name="OffWhite" />
            </collision>
    	    <inertial>
                <mass value="0.1" />
          	    <origin xyz="0 0 0" />
          	    <inertia ixx="0.00001" ixy="0.0"  ixz="0.0"
            				iyy="0.00001" iyz="0.0"
					              izz="0.000005" />
    	    </inertial>
        </link>
        <gazebo reference="$omni_${suffix}_wheel_link">
		<mu1 value="1.0"/>
		<mu2 value="1.0"/>
		<kp value="10000000.0" />
		<kd value="1.0" />
		<fdir1 value="1 0 0"/>
	</gazebo>
    </macro>

    <macro name="omni_wheel_back" params="suffix parent reflect">
        <joint name="${parent}_${suffix}_wheel_joint" type="continuous">
            <axis xyz="0 0 1" />
            <limit effort="100" velocity="100"/>
            <safety_controller k_velocity="10" />
            <origin xyz="-0.1924 0 ${wheel_offset_z}" rpy="${reflect*PI/2} 0 1.57" />
            <parent link="${parent}_link"/>
            <child link="omni_${suffix}_wheel_link"/>
        </joint>
        <link name="omni_${suffix}_wheel_link">
            <visual>
                <origin xyz="0 0 0" rpy="0 0 0" />
                <geometry>
                    <cylinder radius="${wheel_radius}" length="${wheel_length}"/>
                </geometry>
                <material name="Orange" />
            </visual>
            <collision>
                <origin xyz="0 0 0" rpy="0 0 0" />
                <geometry>
                    <cylinder radius="${wheel_radius}" length="${wheel_length}"/>
                </geometry>
                <material name="Orange" />
            </collision>
    	    <inertial>
                <mass value="5" />
          	    <origin xyz="0 0 0" />
          	    <inertia ixx="0.0047" ixy="0.0"  ixz="0.0"
            		                iyy="0.0047" iyz="0.0"
	        				     izz="0.0015" />
    	    </inertial>
        </link>

        <joint name = "${suffix}_wheel_roller_joint1" type="continuous">
            <axis xyz="0 1 0" />
            <limit effort="100" velocity="100"/>
            <origin xyz="${wheel_radius} 0 0" rpy="0 0 0" />
            <parent link="omni_${suffix}_wheel_link"/>
            <child link="${suffix}_roller_link1"/>
        </joint>

        <link name="${suffix}_roller_link1">
            <visual>
                <origin xyz="0 0 0" rpy="1.57 0 0" />
                <geometry>
                    <cylinder radius="${roller_radius}" length="${roller_length}"/>
                </geometry>
                <material name="OffWhite" />
            </visual>
            <collision>
                <origin xyz="0 0 0" rpy="1.57 0 0" />
                <geometry>
                    <cylinder radius="${roller_radius}" length="${roller_length}"/>
                </geometry>
                <material name="OffWhite" />
            </collision>
    	    <inertial>
                <mass value="0.1" />
          	    <origin xyz="0 0 0" />
          	    <inertia ixx="0.00001" ixy="0.0"  ixz="0.0"
            				iyy="0.00001" iyz="0.0"
					              izz="0.000005" />
    	    </inertial>
        </link>

        <joint name = "${suffix}_wheel_roller_joint2" type="continuous">
            <axis xyz="0 1 0" />
            <limit effort="100" velocity="100"/>
            <origin xyz="${wheel_radius*0.866} ${wheel_radius*0.5} 0" rpy="0 0 0.5233" />
            <parent link="omni_${suffix}_wheel_link"/>
            <child link="${suffix}_roller_link2"/>
        </joint>

        <link name="${suffix}_roller_link2">
            <visual>
                <origin xyz="0 0 0" rpy="1.57 0 0" />
                <geometry>
                    <cylinder radius="${roller_radius}" length="${roller_length}"/>
                </geometry>
                <material name="OffWhite" />
            </visual>
            <collision>
                <origin xyz="0 0 0" rpy="1.57 0 0" />
                <geometry>
                    <cylinder radius="${roller_radius}" length="${roller_length}"/>
                </geometry>
                <material name="OffWhite" />
            </collision>
    	    <inertial>
                <mass value="0.1" />
          	    <origin xyz="0 0 0" />
          	    <inertia ixx="0.00001" ixy="0.0"  ixz="0.0"
            				iyy="0.00001" iyz="0.0"
					              izz="0.000005" />
    	    </inertial>
        </link>
        <joint name = "${suffix}_wheel_roller_joint3" type="continuous">
            <axis xyz="0 1 0" />
            <limit effort="100" velocity="100"/>
            <origin xyz="${wheel_radius*0.5} ${wheel_radius*0.866} 0" rpy="0 0 1.0467" />
            <parent link="omni_${suffix}_wheel_link"/>
            <child link="${suffix}_roller_link3"/>
        </joint>

        <link name="${suffix}_roller_link3">
            <visual>
                <origin xyz="0 0 0" rpy="1.57 0 0" />
                <geometry>
                    <cylinder radius="${roller_radius}" length="${roller_length}"/>
                </geometry>
                <material name="OffWhite" />
            </visual>
            <collision>
                <origin xyz="0 0 0" rpy="1.57 0 0" />
                <geometry>
                    <cylinder radius="${roller_radius}" length="${roller_length}"/>
                </geometry>
                <material name="OffWhite" />
            </collision>
    	    <inertial>
                <mass value="0.1" />
          	    <origin xyz="0 0 0" />
          	    <inertia ixx="0.00001" ixy="0.0"  ixz="0.0"
            				iyy="0.00001" iyz="0.0"
					              izz="0.000005" />
    	    </inertial>
        </link>
        <joint name = "${suffix}_wheel_roller_joint4" type="continuous">
            <axis xyz="0 1 0" />
            <limit effort="100" velocity="100"/>
            <origin xyz="0 ${wheel_radius*1} 0" rpy="0 0 1.57" />
            <parent link="omni_${suffix}_wheel_link"/>
            <child link="${suffix}_roller_link4"/>
        </joint>

        <link name="${suffix}_roller_link4">
            <visual>
                <origin xyz="0 0 0" rpy="1.57 0 0" />
                <geometry>
                    <cylinder radius="${roller_radius}" length="${roller_length}"/>
                </geometry>
                <material name="OffWhite" />
            </visual>
            <collision>
                <origin xyz="0 0 0" rpy="1.57 0 0" />
                <geometry>
                    <cylinder radius="${roller_radius}" length="${roller_length}"/>
                </geometry>
                <material name="OffWhite" />
            </collision>
    	    <inertial>
                <mass value="0.1" />
          	    <origin xyz="0 0 0" />
          	    <inertia ixx="0.00001" ixy="0.0"  ixz="0.0"
            				iyy="0.00001" iyz="0.0"
					              izz="0.000005" />
    	    </inertial>
        </link>
        <joint name = "${suffix}_wheel_roller_joint5" type="continuous">
            <axis xyz="0 1 0" />
            <limit effort="100" velocity="100"/>
            <origin xyz="${wheel_radius*-0.5} ${wheel_radius*0.866} 0" rpy="0 0 2.093" />
            <parent link="omni_${suffix}_wheel_link"/>
            <child link="${suffix}_roller_link5"/>
        </joint>

        <link name="${suffix}_roller_link5">
            <visual>
                <origin xyz="0 0 0" rpy="1.57 0 0" />
                <geometry>
                    <cylinder radius="${roller_radius}" length="${roller_length}"/>
                </geometry>
                <material name="OffWhite" />
            </visual>
            <collision>
                <origin xyz="0 0 0" rpy="1.57 0 0" />
                <geometry>
                    <cylinder radius="${roller_radius}" length="${roller_length}"/>
                </geometry>
                <material name="OffWhite" />
            </collision>
    	    <inertial>
                <mass value="0.1" />
          	    <origin xyz="0 0 0" />
          	    <inertia ixx="0.00001" ixy="0.0"  ixz="0.0"
            				iyy="0.00001" iyz="0.0"
					              izz="0.000005" />
    	    </inertial>
        </link>
        <joint name = "${suffix}_wheel_roller_joint6" type="continuous">
            <axis xyz="0 1 0" />
            <limit effort="100" velocity="100"/>
            <origin xyz="${wheel_radius*-0.866} ${wheel_radius*0.5} 0" rpy="0 0 2.617" />
            <parent link="omni_${suffix}_wheel_link"/>
            <child link="${suffix}_roller_link6"/>
        </joint>

        <link name="${suffix}_roller_link6">
            <visual>
                <origin xyz="0 0 0" rpy="1.57 0 0" />
                <geometry>
                    <cylinder radius="${roller_radius}" length="${roller_length}"/>
                </geometry>
                <material name="OffWhite" />
            </visual>
            <collision>
                <origin xyz="0 0 0" rpy="1.57 0 0" />
                <geometry>
                    <cylinder radius="${roller_radius}" length="${roller_length}"/>
                </geometry>
                <material name="OffWhite" />
            </collision>
    	    <inertial>
                <mass value="0.1" />
          	    <origin xyz="0 0 0" />
          	    <inertia ixx="0.00001" ixy="0.0"  ixz="0.0"
            				iyy="0.00001" iyz="0.0"
					              izz="0.000005" />
    	    </inertial>
        </link>

        <joint name = "${suffix}_wheel_roller_joint7" type="continuous">
            <axis xyz="0 1 0" />
            <limit effort="100" velocity="100"/>
            <origin xyz="${wheel_radius*-1} ${wheel_radius*0} 0" rpy="0 0 3.14" />
            <parent link="omni_${suffix}_wheel_link"/>
            <child link="${suffix}_roller_link7"/>
        </joint>

        <link name="${suffix}_roller_link7">
            <visual>
                <origin xyz="0 0 0" rpy="1.57 0 0" />
                <geometry>
                    <cylinder radius="${roller_radius}" length="${roller_length}"/>
                </geometry>
                <material name="OffWhite" />
            </visual>
            <collision>
                <origin xyz="0 0 0" rpy="1.57 0 0" />
                <geometry>
                    <cylinder radius="${roller_radius}" length="${roller_length}"/>
                </geometry>
                <material name="OffWhite" />
            </collision>
    	    <inertial>
                <mass value="0.1" />
          	    <origin xyz="0 0 0" />
          	    <inertia ixx="0.00001" ixy="0.0"  ixz="0.0"
            				iyy="0.00001" iyz="0.0"
					              izz="0.000005" />
    	    </inertial>
        </link>
        <joint name = "${suffix}_wheel_roller_joint8" type="continuous">
            <axis xyz="0 1 0" />
            <limit effort="100" velocity="100"/>
            <origin xyz="${wheel_radius*-0.866} ${wheel_radius*-0.5} 0" rpy="0 0 3.66" />
            <parent link="omni_${suffix}_wheel_link"/>
            <child link="${suffix}_roller_link8"/>
        </joint>

        <link name="${suffix}_roller_link8">
            <visual>
                <origin xyz="0 0 0" rpy="1.57 0 0" />
                <geometry>
                    <cylinder radius="${roller_radius}" length="${roller_length}"/>
                </geometry>
                <material name="OffWhite" />
            </visual>
            <collision>
                <origin xyz="0 0 0" rpy="1.57 0 0" />
                <geometry>
                    <cylinder radius="${roller_radius}" length="${roller_length}"/>
                </geometry>
                <material name="OffWhite" />
            </collision>
    	    <inertial>
                <mass value="0.1" />
          	    <origin xyz="0 0 0" />
          	    <inertia ixx="0.00001" ixy="0.0"  ixz="0.0"
            				iyy="0.00001" iyz="0.0"
					              izz="0.000005" />
    	    </inertial>
        </link>
	<joint name = "${suffix}_wheel_roller_joint9" type="continuous">
            <axis xyz="0 1 0" />
            <limit effort="100" velocity="100"/>
            <origin xyz="${wheel_radius*-0.5} ${wheel_radius*-0.866} 0" rpy="0 0 4.187" />
            <parent link="omni_${suffix}_wheel_link"/>
            <child link="${suffix}_roller_link9"/>
        </joint>

        <link name="${suffix}_roller_link9">
            <visual>
                <origin xyz="0 0 0" rpy="1.57 0 0" />
                <geometry>
                    <cylinder radius="${roller_radius}" length="${roller_length}"/>
                </geometry>
                <material name="OffWhite" />
            </visual>
            <collision>
                <origin xyz="0 0 0" rpy="1.57 0 0" />
                <geometry>
                    <cylinder radius="${roller_radius}" length="${roller_length}"/>
                </geometry>
                <material name="OffWhite" />
            </collision>
    	    <inertial>
                <mass value="0.1" />
          	    <origin xyz="0 0 0" />
          	    <inertia ixx="0.00001" ixy="0.0"  ixz="0.0"
            				iyy="0.00001" iyz="0.0"
					              izz="0.000005" />
    	    </inertial>
        </link>
	<joint name = "${suffix}_wheel_roller_joint10" type="continuous">
            <axis xyz="0 1 0" />
            <limit effort="100" velocity="100"/>
            <origin xyz="${wheel_radius*0} ${wheel_radius*-1} 0" rpy="0 0 4.71" />
            <parent link="omni_${suffix}_wheel_link"/>
            <child link="${suffix}_roller_link10"/>
        </joint>

        <link name="${suffix}_roller_link10">
            <visual>
                <origin xyz="0 0 0" rpy="1.57 0 0" />
                <geometry>
                    <cylinder radius="${roller_radius}" length="${roller_length}"/>
                </geometry>
                <material name="OffWhite" />
            </visual>
            <collision>
                <origin xyz="0 0 0" rpy="1.57 0 0" />
                <geometry>
                    <cylinder radius="${roller_radius}" length="${roller_length}"/>
                </geometry>
                <material name="OffWhite" />
            </collision>
    	    <inertial>
                <mass value="0.1" />
          	    <origin xyz="0 0 0" />
          	    <inertia ixx="0.00001" ixy="0.0"  ixz="0.0"
            				iyy="0.00001" iyz="0.0"
					              izz="0.000005" />
    	    </inertial>
        </link>
	<joint name = "${suffix}_wheel_roller_joint11" type="continuous">
            <axis xyz="0 1 0" />
            <limit effort="100" velocity="100"/>
            <origin xyz="${wheel_radius*0.5} ${wheel_radius*-0.866} 0" rpy="0 0 5.233" />
            <parent link="omni_${suffix}_wheel_link"/>
            <child link="${suffix}_roller_link11"/>
        </joint>

        <link name="${suffix}_roller_link11">
            <visual>
                <origin xyz="0 0 0" rpy="1.57 0 0" />
                <geometry>
                    <cylinder radius="${roller_radius}" length="${roller_length}"/>
                </geometry>
                <material name="OffWhite" />
            </visual>
            <collision>
                <origin xyz="0 0 0" rpy="1.57 0 0" />
                <geometry>
                    <cylinder radius="${roller_radius}" length="${roller_length}"/>
                </geometry>
                <material name="OffWhite" />
            </collision>
    	    <inertial>
                <mass value="0.1" />
          	    <origin xyz="0 0 0" />
          	    <inertia ixx="0.00001" ixy="0.0"  ixz="0.0"
            				iyy="0.00001" iyz="0.0"
					              izz="0.000005" />
    	    </inertial>
        </link>
	<joint name = "${suffix}_wheel_roller_joint12" type="continuous">
            <axis xyz="0 1 0" />
            <limit effort="100" velocity="100"/>
            <origin xyz="${wheel_radius*0.866} ${wheel_radius*-0.5} 0" rpy="0 0 5.757" />
            <parent link="omni_${suffix}_wheel_link"/>
            <child link="${suffix}_roller_link12"/>
        </joint>

        <link name="${suffix}_roller_link12">
            <visual>
                <origin xyz="0 0 0" rpy="1.57 0 0" />
                <geometry>
                    <cylinder radius="${roller_radius}" length="${roller_length}"/>
                </geometry>
                <material name="OffWhite" />
            </visual>
            <collision>
                <origin xyz="0 0 0" rpy="1.57 0 0" />
                <geometry>
                    <cylinder radius="${roller_radius}" length="${roller_length}"/>
                </geometry>
                <material name="OffWhite" />
            </collision>
    	    <inertial>
                <mass value="0.1" />
          	    <origin xyz="0 0 0" />
          	    <inertia ixx="0.00001" ixy="0.0"  ixz="0.0"
            				iyy="0.00001" iyz="0.0"
					              izz="0.000005" />
    	    </inertial>
        </link>
	<gazebo reference="$omni_${suffix}_wheel_link">
		<mu1 value="1.0"/>
		<mu2 value="1.0"/>
		<kp value="10000000.0" />
		<kd value="1.0" />
		<fdir1 value="1 0 0"/>
	</gazebo>
    </macro>

    <omni_wheel parent="base" suffix="l" reflect="1"/>
    <omni_wheel parent="base" suffix="r" reflect="-1"/>
    <omni_wheel_back parent="base" suffix="b" reflect="1"/>

  <!-- ###################################################Transmission################################################### -->
  <transmission name="tran1">
    <type>transmission_interface/SimpleTransmission</type>
    <joint name="base_l_wheel_joint">
      <hardwareInterface>VelocityJointInterface</hardwareInterface>
    </joint>
    <actuator name="motor1">
      <mechanicalReduction>1</mechanicalReduction>
    </actuator>
  </transmission>

  <transmission name="tran2">
    <type>transmission_interface/SimpleTransmission</type>
    <joint name="base_r_wheel_joint">
      <hardwareInterface>VelocityJointInterface</hardwareInterface>
    </joint>
    <actuator name="motor2">
      <mechanicalReduction>1</mechanicalReduction>
    </actuator>
  </transmission>

  <transmission name="tran3">
    <type>transmission_interface/SimpleTransmission</type>
    <joint name="base_b_wheel_joint">
      <hardwareInterface>VelocityJointInterface</hardwareInterface>
    </joint>
    <actuator name="motor3">
      <mechanicalReduction>1</mechanicalReduction>
    </actuator>
  </transmission>
  <gazebo>
      <plugin name="3d_drive_controller" filename="lib3w_motion.so"/>
  </gazebo>
</robot>
